# 08-3. 예외처리하기 - try-catch문
예외처리(exception handling)란, 프로그램 실행 시 발생할 수 있는 예기치 못한 예외의 발생에 대비한 코드를 작성하는 것이며, 
예외처리의 목적은 예외의 발생으로 인한 실행 중인 프로그램의 갑작스런 비정상 종료를 막고, 정상적인 실행상태를 유지할 수 있도록 하는 것이다.

발생한 예외를 처리하지 못하면, 프로그램은 비정상적으로 종료되며, 
처리되지 못한 예외(uncaught exception)는 JVM의 '예외처리기(UncaughtExceptionHandler)'가 받아서 예외의 원인을 화면에 출력한다.

예외를 처리하기 위해서는 try-catch문을 사용하며, 그 구조는 다음과 같다.
```java
try {
  //예외가 발생할 가능성이 있는 문장들을 넣는다.
} catch(Exception1 e1) {
  //Exception1이 발생했을 경우, 이를 처리하기 위한 문장을 적는다.
} catch(Exception2 e2) {
  //Exception2이 발생했을 경우, 이를 처리하기 위한 문장을 적는다.
}
```
하나의 try블럭 다음에는 여러 종류의 예외를 처리할 수 있도록 하나 이상의 catch블럭이 올 수 있으며,
이 중 발생한 예외의 종류와 일치하는 단 한 개의 catch블럭만 수행된다.
발생한 예외의 종류와 일치하는 catch블럭이 없으면 예외는 처리되지 않는다.

if문과 달리, try블럭이나 catch블럭 내에 포함된 문장이 하나뿐이어도 괄호{}를 생략할 수 없다.
하나의 메서드 내에 여러 개의 try-catch문이 사용될 수 있으며, try블럭 또는 catch블럭에 또 다른 try-catch문이 포함될 수 있다. 
catch블럭 내의 코드에서도 예외가 발생할 수 있기 때문이다.

catch블럭의 괄호 내에 선언된 변수는 catch블럭 내에서만 유효하기 때문에, 
위의 모든 catch블럭에 참조변수 'e' 하나 만을 사용해도 된다.
그러나 catch블럭 내에 또 하나의 try-catch문이 포함된 경우, 같은 이름의 참조변수를 사용해서는 안 된다.
```java
```
```
```
ArithmeticException은 산술연산과정에서 오류가 있을 때 발생하는 예외이며, 정수는 0으로 나누는 것이 금지되어있기 때문에 발생했다.
예외처리구문을 추가해서 실행도중 예외가 발생하더라도 프로그램이 실행 도중에 비정상적으로 종료되지 않도록 수정해 보자.
```java
```
```
```
ArithmeticException이 발생하면 ArithmeticException에 해당하는 catch블럭을 찾아서 그 catch블럭 내의 문장들을 실행한 다음 
try-catch문을 벗어나 for문의 다음 반복을 계속 수행하여 작업을 모두 마치고 정상적으로 종료된다.
