# 08-4. try-catch문에서의 흐름
try-catch문에서, 예외가 발생한 경우와 발생하지 않았을 때의 흐름(문장의 실행순서)이 달라진다.
- try블럭 내에서 예외가 발생한 경우,
1. 발생한 예외와 일치하는 catch블럭이 있는지 확인한다.
2. 일치하는 catch블럭을 찾게 되면, 그 catch블럭 내의 문장들을 수행하고 전체 try-catch문을 빠져나가서 그 다음 문장을 계속해서 수행한다.
만일 일치하는 catch블럭을 찾지 못하면, 예외는 처리되지 못한다.
- try블럭 내에서 예외가 발생하지 않은 경우,
1. catch블럭을 거치지 않고 전체 try-catch문을 빠져나가서 수행을 계속한다.
```java
package ch08;

public class ExceptionEx5 {

	public static void main(String[] args) {
		System.out.println(1);
		System.out.println(2);
		try { 
			System.out.println(3);
			System.out.println(0/0);
			System.out.println(4);
		} catch(ArithmeticException ae) {
			System.out.println(5);
		}
		System.out.println(6);
	}

}
```
```
1
2
3
5
6
```
try블럭에서 예외가 발생하면, 예외가 발생한 위치 이후에 있는 try블럭의 문장들은 수행되지 않으므로,
try블럭에 포함시킬 코드의 범위를 잘 선택해야한다.
