# 08-5. 예외의 발생과 catch블럭
catch블럭은 괄호()와 블럭{} 두 부분으로 나눠져 있는데, 괄호()내에는 처리하고자 하는 예외와 같은 타입의 참조변수 하나를 선언해야한다.
예외가 발생하면, 발생한 예외에 해당하는 클래스의 인스턴스가 만들어 진다.

예외가 발생하면, 예외를 처리할 수 있는 catch블럭이 있는지 찾게 된다.
첫 번째 catch블럭부터 차례로 내려가면서 catch블럭의 괄호()내에 선언된 참조변수의 종류와 
생성된 예외클래스의 인스턴스에 instanceof연산자를 이용해서 검사하게 되는데,
검사결과가 true인 catch블럭을 만날 때까지 검사는 계속된다. 검사결과가 true인 catch블럭이 하나도 없으면 예외는 처리되지 않는다.

모든 예외 클래스는 Exception클래스의 자손이므로, 
catch블럭의 괄호()에 Exception클래스 타입의 참조변수를 선언해 놓으면 어떤 종류의 예외가 발생하더라도 이 catch블럭에 의해서 처리된다.
```java
package ch08;

public class ExceptionEx6 {

	public static void main(String[] args) {
		System.out.println(1);
		System.out.println(2);
		try {
			System.out.println(3);
			System.out.println(0/0); 
			System.out.println(4); 
		} catch (Exception e) {
			System.out.println(5);
		} 
		System.out.println (6);
	}

}
```
```
1
2
3
5
6
```

```java
package ch08;

public class ExceptionEx7 {

	public static void main(String[] args) {
		System.out.println(1);
		System.out.println(2);
		try {
			System.out.println(3);
			System.out.println(0/0);
			System.out.println(4);
		} catch(ArithmeticException ae) {
			if (ae instanceof ArithmeticException)
				System.out.println("true");
			System.out.println("ArithmeticException");
		} catch(Exception e) {
			System.out.println("Exception");
		}
		System.out.println(6);
	}

}
```
```
1
2
3
true
ArithmeticException
6
```
try블럭에서 ArithmeticException이 발생하였으므로 catch블럭을 하나씩 차례로 검사하게 되는데, 
첫 번째 검사에서 일치하는 catch블럭을 찾았기 때문에 두 번째 catch블럭은 검사하지 않게 된다. 
만일 try블럭 내에서 ArithmeticException이 아닌 다른 종류의 예외가 발생한 경우에는 
두 번째 catch블럭인 Exception클래스 타입의 참조변수를 선언한 곳에서 처리되었을 것이다.
이처럼, try-catch문의 마지막에 Exception클래스 타입의 참조변수를 선언한 catch블럭을 사용하면, 
어떤 종류의 예외가 발생하더라도 이 catch블럭에 의해 처리되도록 할 수 있다.
***
## printStackTrace()와 getMessage()
예외가 발생했을 때 생성되는 예외 클래스의 인스턴스에는 발생한 예외에 대한 정보가 담겨 있으며,
catch블럭의 괄호()에 선언된 참조변수를 통해 이 인스턴스에 접근할 수 있다.
- printStackTrace(): 예외발생 당시의 호출스택 (Call Stack)에 있었던 메서드의 정보와 예외 메시지를 화면에 출력한다.
- getMessage(): 발생한 예외클래스의 인스턴스에 저장된 메시지를 얻을 수 있다.
```java
package ch08;

public class ExceptionEx8 {

	public static void main(String[] args) {
		System.out.println(1);
		System.out.println(2);
		try {
			System.out.println(3);
			System.out.println(0/0);
			System.out.println(4); 
		} catch(ArithmeticException ae) {
			ae.printStackTrace();
			System.out.println("예외메시지: " + ae.getMessage());
			
		} 
		System.out.println(6);
	}

}
```
```
1
2
3
java.lang.ArithmeticException: / by zero
	at book2/ch08.ExceptionEx8.main(ExceptionEx8.java:10)
예외메시지: / by zero
6
```
***
## 멀티 catch블럭
JDK1.7부터 여러 catch블럭을 '|'기호를 이용해서, 하나의 catch블럭으로 합칠 수 있게 되었으며, 이를 '멀티 catch블럭'이라 한다. 
'멀티 catch블럭'을 이용하면 중복된 코드를 줄일 수 있다. 그리고 '|'기호로 연결할 수 있는 예외 클래스의 개수에는 제한이 없다.
```java
try {
  ...
} catch(ExceptionA | ExceptionB e) {
  e.printStackTrace();
}
```
만일 멀티 catch블럭의 '|'기호로 연결된 예외 클래스가 조상과 자손의 관계에 있다면 컴파일 에러가 발생한다.
왜냐하면, 두 예외 클래스가 조상과 자손의 관계에 있다면, 그냥 다음과 같이 조상 클래스만 써주는 것과 똑같기 때문이다.

하지만, 멀티 catch는 하나의 catch블럭으로 여러 예외를 처리하는 것이기 때문에, 실제로 어떤 예외가 발생한 것인지 알 수 없다.
그래서 참조변수 e로 멀티 catch블럭에 '|'기호로 연결된 예외 클래스들의 공통 분모인 조상 예외 클래스에 선언된 멤버만 사용할 수 있다.
```java
try {
  ...
} catch(ExceptionA | ExceptionB e) {
  e.methodA(); //에러. ExceptionA에 선언된 methodA()는 호출불가
  if(e instanceof ExceptionA) {
    ExceptionA e1 = (ExceptionA)e;
    e1.methodA(); //OK. ExceptionA에 선언된 메서드 호출가능
  } else { // if(e instanceof ExceptionB)
    ...
  }
  e.printStackTrace();
}
```
필요하다면, 위와 같이 instanceof로 어떤 예외가 발생한 것인지 확인하고 개별적으로 처리할 수는 있다. 
그러나 이렇게까지 해가면서 catch블럭을 합칠 일은 거의 없을 것이다.
마지막으로 멀티 catch블럭에 선언된 참조변수 e는 상수이므로 값을 변경할 수 없다는 제약이 있다.
