# 08-9. 자동 자원 반환 - try-with-resources
JDK1.7부터 try-with-resources문이라는 try-catch문의 변형이 새로 추가되었다.

주로 입출력에 사용되는 클래스 중에서는 사용한 후에 꼭 닫아 줘야 하는 것들이 있다.
그래야 사용했던 자원(resources)이 반환되기 때문이다.
```java
try {
  fis = new Fileinputstream("score.dat");
  dis = new DataInputStream(fis);
} catch(IOException ie) {
  ie.printStackTrace();
} finally {
  try {
    if(dis! = null)
    dis.close();
  } catch(IOException ie) {
    ie.printStackTrace();
  }
}
```
위의 코드는 DataInputStream을 사용해서 파일로부터 데이터를 읽는 코드인데,
데이터를 읽는 도중에 예외가 발생하더라도 DataInputStream이 닫히도록 finally블럭 안에 close()를 넣었다.
그런데, close() 역시 예외를 발생시킬 수 있기 때문에 finally블럭 안에 try-catch문을 추가해서 예외를 처리하도록 했다.
코드가 복잡해져서 별로 보기에 좋지 않다. 더 나쁜 것은 try블럭과 finally블럭에서 모두 예외가 발생하면, try블럭의 예외는 무시된다는 것이다.

이러한 점을 개선하기 위해서 try-with-resources문이 추가된 것이다
```java
//괄호()안에 두 문장 이상 넣을 경우 ';'로 구분한다.
try(FileInputStream fis = new FileInputStream("score.dat");
    DataInputStream dis = new DataInputStream(fis)) {
  while(true) {
    score = dis.readInt();
    System.out.println(score);
    sum += score;
  }
} catch (EOFException e) {
  System.out.println("점수의 총합은 " + sum + "입니다.");
} catch (IOException ie) {
  ie.printStackTrace();
}
```
try-with-resources문의 괄호()안에 객체를 생성하는 문장을 넣으면, 
이 객체는 따로 close()를 호출하지 않아도 try블럭을 벗어나는 순간 자동적으로 close()가 호출된다. 
그 다음에 catch블럭 또는 finally블럭이 수행된다.

이처럼 try-with-resources문에 의해 자동으로 객체의 close()가 호출될 수 있으려면,
클래스가 AutoCloseable이라는 인터페이스를 구현한 것이어야만 한다.
```java
public interface AutoCloseable {
  void close() throws Exception;
}
```
위의 인터페이스는 각 클래스에서 적절히 자원 반환작업을 하도록 구현되어 있다. 
그런데, 위의 코드를 잘 보면 close()도 Exception을 발생시킬 수 있다. 
만일 자동 호출된 close()에서 예외가 발생하면 어떻게 될까?
```java
package ch08;

public class TryWithResourceEx {

	public static void main(String[] args) {
		try(CloseableResource cr = new CloseableResource()) {
			cr.exceptionwork(false); //예외가 발생하지 않는다.
		} catch(WorkException e) {
			e.printStackTrace();
		} catch(CloseException e) {
			e.printStackTrace();
		}
		System.out.println();
		
		try(CloseableResource cr = new CloseableResource()) {
			cr.exceptionwork(true); //예외가 발생한다.
		} catch(WorkException e) {
			e.printStackTrace();
		} catch(CloseException e) {
			e.printStackTrace();
		}
	}
	
}
			
class CloseableResource implements AutoCloseable {
	public void exceptionwork(boolean exception) throws WorkException {
		System.out.println("exceptionwork(" + exception + ")가 호출됨");
	
		if(exception)
			throw new WorkException("WorkException발생!!!");
	}
	
	public void close() throws CloseException {
		System.out.println("close()가 호출됨");
		throw new CloseException("CloseException발생!!!");
	}
}

class WorkException extends Exception {
	WorkException(String msg) { super(msg); }
}

class CloseException extends Exception {
	CloseException(String msg) { super(msg); }
}
```
```
exceptionwork(false)가 호출됨
close()가 호출됨
ch08.CloseException: CloseException발생!!!
	at book2/ch08.CloseableResource.close(TryWithResourceEx.java:36)
	at book2/ch08.TryWithResourceEx.main(TryWithResourceEx.java:8)
exceptionwork(true)가 호출됨
close()가 호출됨
ch08.WorkException: WorkException발생!!!
	at book2/ch08.CloseableResource.exceptionwork(TryWithResourceEx.java:31)
	at book2/ch08.TryWithResourceEx.main(TryWithResourceEx.java:16)
	Suppressed: ch08.CloseException: CloseException발생!!!
		at book2/ch08.CloseableResource.close(TryWithResourceEx.java:36)
		at book2/ch08.TryWithResourceEx.main(TryWithResourceEx.java:17)
```
main메서드의 두 번째 try-catch문을 보자.
먼저 exceptionWork()에서 발생한 예외에 대한 내용이 출력되고, close()에서 발생한 예외는 '억제된(suppressed)'이라는 의미의 머리말과 함께 출력되었다.

두 예외가 동시에 발생할 수는 없기 때문에, 실제 발생한 예외를 WorkException으로 하고, CloseException은 억제된 예외로 다룬다. 
억제된 예외에 대한 정보는 실제로 발생한 예외인 WorkException에 저장된다.

Throwable에는 억제된 예외와 관련된 다음과 같은 메서드가 정의되어 있다.
```java
void addSuppressed(Throwable exception) //억제된 예외를 추가
Throwable[] getSuppressed() //억제된 예외(배열)을 반환
```
만일 기존의 try-catch문을 사용했다면, 먼저 발생한 WorkException은 무시되고, 마지막으로 발생한 CloseException에 대한 내용만 출력되었을 것이다.
